<?xml version='1.0'?>

<robot name="mobile_manipulator_forklift" xmlns:xacro="http://www.ros.org/wiki/xacro">
  <xacro:include filename="$(find forklift_project)/urdf/common_macros.xacro" />

  <gazebo>
    <static>true</static>
  </gazebo>

<xacro:include filename="$(find forklift_project)/urdf/mobile_manipulator_forklift.urdf.gazebo" />


  <!--############################### -->
  <!-- MOBILE PLATFORM -->
  <!--############################### -->
  <origin xyz="0 0 0" rpy="0 0 0"/>
  <link name="base_footprint"/>

  <joint name="base_joint" type="fixed">
    <parent link="base_footprint"/>
    <child link="mobile_body_link" />
    <origin xyz="0 0 0" rpy="0 0 0"/>
  </joint>

  <!-- MOBILE BASE -->
  <!-- ==================================== -->
  <xacro:link_box link_name="mobile_body_link" length="2.0" width="1.5" height="0.8" density="1" mesh_name="nofile">
  <!-- origin visual -->
  <origin xyz="0 0 0.6" rpy="0 0 0"/>
  <!-- origin collision -->
  <origin xyz="0 0 0.6" rpy="0 0 0"/>
  <!-- origin interia -->
  <origin xyz="0 0 0.6" rpy="0 0 0"/>
</xacro:link_box>




  <!-- FRONT LEFT WHEEL -->
  <!-- ==================================== -->
  <joint type="continuous" name="wheel_front_left_joint">
    <origin xyz="0.60 0.95 0.40" rpy="-${pi/2} 0 0"/>
    <child link="wheel_front_left_link"/>
    <parent link="mobile_body_link"/>
    <axis xyz="0 0 1" rpy="0 0 0"/>
    <limit effort="100" velocity="100"/>
  </joint>

  <xacro:link_cylinder link_name="wheel_front_left_link" radius="0.4" length="0.4" density="1" mesh_name="nofile" >
    <!-- origin visual -->
    <origin xyz="0 0 0" rpy="0 0 0"/>
    <!-- origin collision -->
    <origin xyz="0 0 0" rpy="0 0 0"/>
    <!-- origin interia -->
    <origin xyz="0 0 0" rpy="0 0 0"/>
  </xacro:link_cylinder>


  <!-- FRONT RIGHT WHEEL -->
  <!-- ==================================== -->
  <joint type="continuous" name="wheel_front_right_joint">
    <origin xyz="0.60 -0.95 0.40" rpy="-${pi/2} 0 0"/>
    <child link="wheel_front_right_link"/>
    <parent link="mobile_body_link"/>
    <axis xyz="0 0 1" rpy="0 0 0"/>
    <limit effort="100" velocity="100"/>
  </joint>

  <xacro:link_cylinder link_name="wheel_front_right_link" radius="0.4" length="0.4" density="1" >
    <!-- origin visual -->
    <origin xyz="0 0 0" rpy="0 0 0"/>
    <!-- origin collision -->
    <origin xyz="0 0 0" rpy="0 0 0"/>
    <!-- origin interia -->
    <origin xyz="0 0 0" rpy="0 0 0"/>
  </xacro:link_cylinder>


  <!-- REAR LEFT WHEEL -->
  <!-- ==================================== -->
  <joint type="continuous" name="wheel_rear_left_joint">
    <origin xyz="-0.60 0.95 0.40" rpy="-${pi/2} 0 0"/>
    <child link="wheel_rear_left_link"/>
    <parent link="mobile_body_link"/>
    <axis xyz="0 0 1" rpy="0 0 0"/>
    <limit effort="100" velocity="100"/>
  </joint>

  <xacro:link_cylinder link_name="wheel_rear_left_link" radius="0.4" length="0.4" density="1" mesh_name="nofile" >
    <!-- origin visual -->
    <origin xyz="0 0 0" rpy="0 0 0"/>
    <!-- origin collision -->
    <origin xyz="0 0 0" rpy="0 0 0"/>
    <!-- origin interia -->
    <origin xyz="0 0 0" rpy="0 0 0"/>
  </xacro:link_cylinder>


  <!-- REAR RIGHT WHEEL -->
  <!-- ==================================== -->
  <joint type="continuous" name="wheel_rear_right_joint">
    <origin xyz="-0.60 -0.95 0.40" rpy="-${pi/2} 0 0"/>
    <child link="wheel_rear_right_link"/>
    <parent link="mobile_body_link"/>
    <axis xyz="0 0 1" rpy="0 0 0"/>
    <limit effort="100" velocity="100"/>
  </joint>

  <xacro:link_cylinder link_name="wheel_rear_right_link" radius="0.4" length="0.4" density="1" mesh_name="nofile" >
    <!-- origin visual -->
    <origin xyz="0 0 0" rpy="0 0 0"/>
    <!-- origin collision -->
    <origin xyz="0 0 0" rpy="0 0 0"/>
    <!-- origin interia -->
    <origin xyz="0 0 0" rpy="0 0 0"/>
  </xacro:link_cylinder>



  <!--############################### -->
  <!-- ROBOTIC ARM -->
  <!--############################### -->

    <!-- ARM BASE -->
    <!-- ==================================== -->
    <joint type="revolute" name="arm_base_joint">
      <origin xyz="0 0 1" rpy="0 0 0"/>
      <child link="arm_base_link"/>
      <parent link="mobile_body_link"/>
      <axis xyz="0 0 1" rpy="0 0 0"/>
      <limit effort="100" velocity="100" lower="-${pi}" upper="${pi}"/>
    </joint>

    <xacro:link_cylinder link_name="arm_base_link" radius="0.1" length="0.6" density="1" mesh_name="nofile" >
      <!-- origin visual -->
      <origin xyz="0 0 0.3" rpy="0 0 0"/>
      <!-- origin collision -->
      <origin xyz="0 0 0.3" rpy="0 0 0"/>
      <!-- origin interia -->
      <origin xyz="0 0 0.3" rpy="0 0 0"/>
    </xacro:link_cylinder>

    <!-- LINK 1 -->
    <!-- ==================================== -->
    <joint type="revolute" name="link_1_joint">
      <origin xyz="0 0 0.5775" rpy="0 0 0"/>
      <child link="link_1_link"/>
      <parent link="arm_base_link"/>
      <axis xyz="0 1 0" rpy="0 0 0"/>
      <limit effort="100" velocity="100" lower="-${pi/2}" upper="${pi/2}"/>
    </joint>

    <xacro:link_cylinder link_name="link_1_link" radius="0.1" length="1.155" density="1" mesh_name="nofile" >
      <!-- origin visual -->
      <origin xyz="0 0 0.5775" rpy="0 0 0"/>
      <!-- origin collision -->
      <origin xyz="0 0 0.5775" rpy="0 0 0"/>
      <!-- origin interia -->
      <origin xyz="0 0 0.5775" rpy="0 0 0"/>
    </xacro:link_cylinder>


    <!-- LINK 2 -->
    <!-- ==================================== -->
    <joint type="revolute" name="link_2_joint">
      <origin xyz="0 0 1.155" rpy="0 0 0"/>
      <child link="link_2_link"/>
      <parent link="link_1_link"/>
      <axis xyz="0 1 0" rpy="0 0 0"/>
      <limit effort="100" velocity="100" lower="-${pi/2}" upper="${pi/2}"/>
    </joint>

    <xacro:link_cylinder link_name="link_2_link" radius="0.1" length="1.155" density="1" mesh_name="nofile" >
      <!-- origin visual -->
      <origin xyz="0 0 0.5775" rpy="0 0 0"/>
      <!-- origin collision -->
      <origin xyz="0 0 0.5775" rpy="0 0 0"/>
      <!-- origin interia -->
      <origin xyz="0 0 0.5775" rpy="0 0 0"/>
    </xacro:link_cylinder>

    <!-- LINK 3 -->
    <!-- ==================================== -->
    <joint type="revolute" name="link_3_joint">
      <origin xyz="0 0 1.155" rpy="0 0 0"/>
      <child link="link_3_link"/>
      <parent link="link_2_link"/>
      <axis xyz="0 0 1" rpy="0 0 0"/>
      <limit effort="100" velocity="100" lower="-${pi/2}" upper="${pi/2}"/>
    </joint>

    <xacro:link_cylinder link_name="link_3_link" radius="0.1" length="0.6" density="1" mesh_name="nofile" >
      <!-- origin visual -->
      <origin xyz="0 0 0.3" rpy="0 0 0"/>
      <!-- origin collision -->
      <origin xyz="0 0 0.3" rpy="0 0 0"/>
      <!-- origin interia -->
      <origin xyz="0 0 0.3" rpy="0 0 0"/>
    </xacro:link_cylinder>

    <!-- LINK 4 -->
    <!-- ==================================== -->
    <joint type="revolute" name="link_4_joint">
      <origin xyz="0 0 0.6" rpy="0 0 0"/>
      <child link="link_4_link"/>
      <parent link="link_3_link"/>
      <axis xyz="0 0 1" rpy="0 0 0"/>
      <limit effort="100" velocity="100" lower="-${pi/2}" upper="${pi/2}"/>
    </joint>

    <xacro:link_cylinder link_name="link_4_link" radius="0.1" length="0.4" density="1" mesh_name="nofile" >
      <!-- origin visual -->
      <origin xyz="0 0 0.2" rpy="0 0 0"/>
      <!-- origin collision -->
      <origin xyz="0 0 0.2" rpy="0 0 0"/>
      <!-- origin interia -->
      <origin xyz="0 0 0.2" rpy="0 0 0"/>
    </xacro:link_cylinder>

</robot>
